Traceback (most recent call last):
  File "/media/DATA/DoctoratTlemcen/Git/mixim/mixim/sumo-launchd.py", line 675, in <module>
    main()
  File "/media/DATA/DoctoratTlemcen/Git/mixim/mixim/sumo-launchd.py", line 670, in main
    wait_for_connections(options.command, options.shlex, options.port, options.bind, options.daemonize, options.kill, options.pidfile, options.keep_temp)
  File "/media/DATA/DoctoratTlemcen/Git/mixim/mixim/sumo-launchd.py", line 541, in wait_for_connections
    listener.bind((bind_address, sumo_port))
  File "/usr/lib/python2.7/socket.py", line 224, in meth
    return getattr(self._sock,name)(*args)
socket.error: [Errno 98] Address already in use
